Workbook

Sheet Calculo
B2: Calculo de cuotas
B5: Monto solicitado | C5: =+'Plan de pagos'!L15 -> 3000
B7: Interes Mensual | C7: =+'Plan de pagos'!G7 -> 0.06
B9: Plazo en meses | C9: =+'Plan de pagos'!G11 -> 12
B11: Cuota Mensual | C11: =PMT(C7,C9,C5)*-1 -> 357.83109
B13: Cuota catorcenal o quincenal | C13: =C11/2 -> 178.91554
B15: Total a pagar | C15: =C9*C11 -> 4293.9731

Sheet Otros cargos
A1: 1. Contexto
A3: Actualmente, los costos operativos (visitas de campo y papelería) son absorbidos por la institución. Para mejorar márgenes de utilidad, proponemos trasladarlos parcialmente al cliente de manera transparente y justa. | H3: 300 | I3: 4999
A5: 2. Costos a trasladar
A7: a) Combustible (Moto 125 cc)
A8: Consumo estimado: 35 km/l
A9: Distancia promedio por cliente (50 km radio):
A10: Litros estimados por viaje: 1.4 L
A11: Precio diésel: C$ 49/L
A12: Costo por visita: 1.4L × 49 = C$ 68.60
A14: b) Papelería y expediente
A16: Rema de papel: C$ 135.00
A17: Promedio de hojas por expediente 50 hojas: C$ 67.50
A18: Folder tamaño carta: C$ 5.00
A19: Total: C$ 72.50
A21: 3. Resumen de cargos
A23: Concepto | B23: Monto por cliente (C$)
A24: Combustible | B24: 68.6
A25: Verificacion de garantia mobiliaria | B25: =ROUND(B24,2) -> 68.6
A26: Papelería + Folder | B26: 72.5
A27: Total recargo inicial | B27: =ROUND(SUM(B24:B26),2) -> 209.7
A28: Combustible por la cantidade de visitas por cobro de acuerdo al numero de cuotas del plan de pago | B28: combustible x cantidad de cuotas
A30: Aplicación
A32: Creditos de 300 a 1000 | C32: Cargo
A33: Cargo por filtro en centrales de riesgo | B33: TRUE | C33: =ROUND(6*36.6243,2) -> 219.75
A34: Cargo por verificación | B34: TRUE | C34: =+B25 -> 68.6
A35: Cargo por papeleria | B35: TRUE | C35: =ROUND(B26,2) -> 72.5
B36: Total de cargos: | C36: =ROUND(SUM(C33:C35),2) -> 360.85
B37: Equivalente en $ | C37: =+C36/36.6243 -> 9.852748
A39: Creditos mayores a 1000 | C39: Cargo
A40: Cargo por filtro en centrales de riesgo | B40: TRUE | C40: =+C33 -> 219.75
A41: Cargo por verificación | B41: TRUE | C41: =+C34 -> 68.6
A42: Cargo por papeleria | B42: TRUE | C42: =+B26 -> 72.5
A43: Cargo por combustible | B43: TRUE | C43: =+C41*C44 -> 1646.4
A44: Cantidad de visitas según plan de pago/ Nº de cuotas | B44: TRUE | C44: =IF('Plan de pagos'!L7="Deposito",0,MAX('Plan de pagos'!D:D)) -> 24
A45: Combustible – primera visita | B45: TRUE | C45: 68.6
B46: Total de cargos: | C46: =+SUM(C40:C43)+C45 -> 2075.85
B47: Equivalente en $ | C47: =+C46/36.6243 -> 56.679582

Sheet rptPlanDePagos
P1: CREDIBLAMEN S.A.
P4: CREDIBLAMEN S.A.
P6: CALENDARIO DE PAGO
AR9: Fecha y Hora de Impresión:
D12: Código cliente:
X13: Nombre del Cliente:
K14: 0010410750006Q | AJ14: Wlmer Antonio Yescas Mora | AY14: Metodología: | BD14: Individual
D17: Código Crédito:
L18: =+K14 -> 0010410750006Q | W18: Ciclo: | Z18: 1 | AI18: Producto: | AP18: PYME COMERCIO
AN22: Fecha de Desembolso:
AU23: 45838 | BB23: Tasa de Interés: | BK23: 72.00 %
O24: 1000
F25: Monto Aprobado:
T26: Plazo en Meses: | AF26: 12
AN29: Fecha de Vencimiento:
AU30: =+I96 -> 46207
BB31: Tasa de Mora:
BK32: 18.00 %
F36: Monto Entregado: | O36: =+O24 -> 1000
T37: N. de Cuotas: | AD37: 24
AN42: TCEA:
BB43: Comisión:
BK44: 0.00 %
T47: Tipo Cuota: | AD47: Quincenal
F48: T/C Desembolso: | O48: 36.6243
AN52: Analista:
AU53: Angelica Orozco.
AC56: CASA MATRIZ
E57: Moneda: | O57: Dólar | T57: Sucursal:
AN60: Cobrador:
AU61: Gestor de cobros
B69: PLAN DE PAGOS
A71: Dia | B71: Cuota | I71: Fecha | Q71: D_Int | R71: Capital | AA71: Comisión | AK71: Desliz | AQ71: Interés | AS71: Cuota | AV71: Sal_Capital
A72: =+TEXT(I72,"DDD") -> lun | B72: 0 | I72: =+AU23 -> 45838 | Q72: 0 | AV72: 1000
A73: =+TEXT(I73,"DDD") -> sáb | B73: 1 | I73: 45857 | Q73: 18 | R73: =+AS73-AQ73 -> 25 | AA73: 0 | AK73: 0 | AQ73: =+AV72*6%/30*Q73 -> 36 | AS73: 61 | AV73: =+AV72-R73 -> 975
A74: =+TEXT(I74,"DDD") -> lun | B74: 2 | I74: =+I73+Q74 -> 45873 | Q74: 16 | R74: =+AS74-AQ74 -> 29.8 | AA74: 0 | AK74: 0 | AQ74: =+AV73*6%/30*Q74 -> 31.2 | AS74: 61 | AV74: =+AV73-R74 -> 945.2
A75: =+TEXT(I75,"DDD") -> mar | B75: 3 | I75: =+I74+Q75 -> 45888 | Q75: 15 | R75: =+AS75-AQ75 -> 32.644 | AA75: 0 | AK75: 0 | AQ75: =+AV74*6%/30*Q75 -> 28.356 | AS75: 61 | AV75: =+AV74-R75 -> 912.556
A76: =+TEXT(I76,"DDD") -> jue | B76: 4 | I76: =+I75+Q76 -> 45904 | Q76: 16 | R76: =+AS76-AQ76 -> 31.798208 | AA76: 0 | AK76: 0 | AQ76: =+AV75*6%/30*Q76 -> 29.201792 | AS76: 61 | AV76: =+AV75-R76 -> 880.75779
A77: =+TEXT(I77,"DDD") -> vie | B77: 5 | I77: =+I76+Q77 -> 45919 | Q77: 15 | R77: =+AS77-AQ77 -> 34.577266 | AA77: 0 | AK77: 0 | AQ77: =+AV76*6%/30*Q77 -> 26.422734 | AS77: 61 | AV77: =+AV76-R77 -> 846.18053
A78: =+TEXT(I78,"DDD") -> sáb | B78: 6 | I78: =+I77+Q78 -> 45934 | Q78: 15 | R78: =+AS78-AQ78 -> 35.614584 | AA78: 0 | AK78: 0 | AQ78: =+AV77*6%/30*Q78 -> 25.385416 | AS78: 61 | AV78: =+AV77-R78 -> 810.56594
...

Sheet Plan de pagos
H1: Calendario de pago
E3: Nombre del Cliente: | G3: Arlen del Socorro Arauz Hernandez | K3: ID Cliente
E4: Doc de identidad: | G4: 3610805910000J | K4: =IFERROR(_xlfn.XLOOKUP(G4,Hoja3!C:C,Hoja3!A:A)," ") -> 1240
E5: Tipo de Producto: | G5: MIPYME COMERCIO | H5: Microcreditos | K5: Nuevo
E7: Interes corriente mensual : | G7: 0.06 | K7: Cobrador: | L7: Gestor de cobro
E8: Interes corriente anual : | G8: =G7*12 -> 0.72 | H8: =+G8/12 -> 0.06 | K8: Promotor: | L8: Carlos Pineda | S8: Cuota | T8: =+G15 -> 187.67
E10: Interes moratorio: | G10: =+G8/4 -> 0.18 | H10: =+XIRR(K20:K44,E20:E44,0)*1 -> 1.2454851 | I10: =(1 + H10)^(1/12) - 1 -> 0.069734122 | K10: Tipo de cuota | L10: Nivelada | S10: =+IF(G13="Mensual",G11,G11*2) -> 24 | T10: =+VLOOKUP(S10,D:L,6,0) -> 8.94 | U10: Comision
B11: =+IF(G13="Mensual",G11,G11*2) -> 24 | E11: Plazo en meses: | G11: 12 | K11: Fecha de desembolso | L11: 45996 | Q11: =IF(G13="Mensual","Día",IF(G13="Quincenal","Días"," ")) -> Días | S11: =+IF(G13="Mensual",G11,G11*2)-1 -> 23 | T11: =+SUMIFS(L:L,D:D,S11) -> 319.2 | U11: =+M22 -> 8.75
G12: =+IF(G13="Mensual",G11,G11*2) -> 24
E13: Frecuencia de pago: | G13: Quincenal | H13: 6 | I13: 21 | K13: 1er dia de pago | L13: 46015 | O13: =+L15*7% -> 210 | P13: =+DAY(L13) -> 24 | R13: =+IF(P13>15,"Segunda quincena","Primera Quincena") -> Segunda quincena | S13: Total | T13: =+T10+T11+U13 -> 336.89 | U13: =+U11 -> 8.75
E15: Cuota: | G15: =ROUND(ROUND(IF(G13="Mensual",Calculo!C11,Calculo!C11/2)-H15,2)+M21,2) -> 187.67 | K15: Saldo Inicial | L15: 3000 | T15: =+ABS(T13) -> 336.89
G16: =IF(G13="Mensual",Calculo!C11,Calculo!C13) -> 178.91554 | H16: =+G15-G16 -> 8.7544559 | P16: =+L15*7% -> 210
E17: % comision por desembolso | G17: =+IF(L15>4999,5%,7%) -> 0.07 | K17: Otros cargos | L17: Aplica | P17: =+L15*G17-J73 -> 0
K18: =ROUND(L18/MAX(D:D),2) -> 8.75 | L18: =IF(L17="Aplica",IF(L15<5000,L15*7%,L15*5%),0) -> 210 | M18: =+MAX(D:D) -> 24
B19: Dia | D19: Nº | E19: Fecha | G19: Nº dias | H19: Principal | I19: Interes | J19: Comision por desembolso | K19: Cuota | L19: Saldo Capital | M19: Gastos fijos | P19: =+M21+P17 -> 8.75
D20: 0 | E20: =+L11 -> 45996 | K20: =+L15*-1 -> -3000
B21: =IFERROR(TEXT(R21,"DDD"),"") -> mié | C21: =+E21 -> 46015 | D21: 1 | E21: =IFERROR(IF(B21="dom",R21+1,R21)," ") -> 46015 | G21: =+IFERROR(E21-L11," ") -> 19 | H21: =ROUND($G$15-I21-M21,2) -> 64.92 | I21: =ROUND(L15*H8/30*G21,2) -> 114 | J21: =+M21 -> 8.75 | K21: =+G15 -> 187.67 | L21: =ROUND(L15-H21,4) -> 2935.08 | M21: =IF(D21<=$M$18,$K$18,0) -> 8.75 | N21: =+H21+I21+J21-K21 -> 0 | O21: =IF(L21=MIN($L$21:$L$68),"min"," ") | P21: =IFERROR(IF(O21="Min",$T$13," ")+M21,"") | Q21: =+R21-L11 -> 19 | R21: =+L13 -> 46015
B22: =IFERROR(TEXT(R22,"DDD"),"") -> mié | C22: =+IF(B22="dom",R22+1,R22) -> 46043 | D22: =IFERROR(IF(D21+1>$B$11," ",D21+1)," ") -> 2 | E22: =IFERROR(IF(B22="dom",R22+1,R22)," ") -> 46043 | G22: =IFERROR(E22-E21,0) -> 28 | H22: =IF(D22=" ",0,IF(D22=$M$18,K22-I22-M22,ROUND($G$16-I22,2))) -> 14.56 | I22: =IFERROR(ROUND(IFERROR(L21*$H$8/30*G22," "),2),0) -> 164.36 | J22: =+M22 -> 8.75 | K22: =+G15 -> 187.67 | L22: =IF(H22=0," ",ROUND(IFERROR(L21-H22," "),2)) -> 2920.52 | M22: =IF(D22<=$M$18,$K$18,0) -> 8.75 | N22: =+H22+I22+J22-K22 -> 0 | O22: =IF(L22=MIN($L$21:$L$68),"min"," ") | P22: =IFERROR(IF(O22="Min",$T$13," "),"") | Q22: =IFERROR(R22-R21," ") -> 28 | R22: =IF(D22=" ","",IF($G$13="Catorcenal",R21+14,_xlfn.XLOOKUP(D22,Calendario!G:G,Calendario!F:F))) -> 46043
A23: =IFERROR(IF(D22+1>$B$11," ",D22+1)," ") -> 3 | B23: =IFERROR(TEXT(R23,"DDD"),"") -> vie | C23: =IF($G$13="Catorcenal",R22+14,_xlfn.XLOOKUP(A23,Calendario!G:G,Calendario!F:F)) -> 46059 | D23: =IFERROR(IF(D22+1>$B$11," ",D22+1)," ") -> 3 | E23: =IFERROR(IF(B23="dom",R23+1,R23)," ") -> 46059 | G23: =IFERROR(E23-E22,0) -> 16 | H23: =IF(D23=" ",0,IF(D23=$M$18,K23-I23-M23,ROUND($G$16-I23,2))) -> 85.46 | I23: =IFERROR(ROUND(IFERROR(L22*$H$8/30*G23," "),2),0) -> 93.46 | J23: =+M23 -> 8.75 | K23: =IF(D23=" "," ",K22) -> 187.67 | L23: =IF(H23=0," ",ROUND(IFERROR(L22-H23," "),2)) -> 2835.06 | M23: =IF(D23<=$M$18,$K$18,0) -> 8.75 | N23: =+H23+I23+J23-K23 -> 0 | O23: =IF(L23=MIN($L$21:$L$68),"min"," ") | P23: =IFERROR(IF(O23="Min",$T$13," "),"") | Q23: =IFERROR(R23-R22," ") -> 16 | R23: =IF(D23=" ","",IF($G$13="Catorcenal",R22+14,_xlfn.XLOOKUP(D23,Calendario!G:G,Calendario!F:F))) -> 46059
A24: =IFERROR(IF(A23+1>$B$11," ",A23+1)," ") -> 4 | B24: =IFERROR(TEXT(R24,"DDD"),"") -> sáb | C24: =IF($G$13="Catorcenal",C23+14,_xlfn.XLOOKUP(A24,Calendario!G:G,Calendario!F:F)) -> 46074 | D24: =IFERROR(IF(D23+1>$B$11," ",D23+1)," ") -> 4 | E24: =IFERROR(IF(B24="dom",R24+1,R24)," ") -> 46074 | G24: =IFERROR(E24-E23,0) -> 15 | H24: =IF(D24=" ",0,IF(D24=$M$18,K24-I24-M24,ROUND($G$16-I24,2))) -> 93.87 | I24: =IFERROR(ROUND(IFERROR(L23*$H$8/30*G24," "),2),0) -> 85.05 | J24: =+M24 -> 8.75 | K24: =IF(D24=" "," ",K23) -> 187.67 | L24: =IF(H24=0," ",ROUND(IFERROR(L23-H24," "),2)) -> 2741.19 | M24: =IF(D24<=$M$18,$K$18,0) -> 8.75 | N24: =+H24+I24+J24-K24 -> 0 | O24: =IF(L24=MIN($L$21:$L$68),"min"," ") | P24: =IFERROR(IF(O24="Min",$T$13," "),"") | Q24: =IFERROR(R24-R23," ") -> 15 | R24: =IF(D24=" ","",IF($G$13="Catorcenal",R23+14,_xlfn.XLOOKUP(D24,Calendario!G:G,Calendario!F:F))) -> 46074
A25: =IFERROR(IF(A24+1>$B$11," ",A24+1)," ") -> 5 | B25: =IFERROR(TEXT(R25,"DDD"),"") -> vie | C25: =IF($G$13="Catorcenal",C24+14,_xlfn.XLOOKUP(A25,Calendario!G:G,Calendario!F:F)) -> 46087 | D25: =IFERROR(IF(D24+1>$B$11," ",D24+1)," ") -> 5 | E25: =IFERROR(IF(B25="dom",R25+1,R25)," ") -> 46087 | G25: =IFERROR(E25-E24,0) -> 13 | H25: =IF(D25=" ",0,IF(D25=$M$18,K25-I25-M25,ROUND($G$16-I25,2))) -> 107.65 | I25: =IFERROR(ROUND(IFERROR(L24*$H$8/30*G25," "),2),0) -> 71.27 | J25: =+M25 -> 8.75 | K25: =IF(D25=" "," ",K24) -> 187.67 | L25: =IF(H25=0," ",ROUND(IFERROR(L24-H25," "),2)) -> 2633.54 | M25: =IF(D25<=$M$18,$K$18,0) -> 8.75 | N25: =+H25+I25+J25-K25 -> 0 | O25: =IF(L25=MIN($L$21:$L$68),"min"," ") | P25: =IFERROR(IF(O25="Min",$T$13," "),"") | Q25: =IFERROR(R25-R24," ") -> 13 | R25: =IF(D25=" ","",IF($G$13="Catorcenal",R24+14,_xlfn.XLOOKUP(D25,Calendario!G:G,Calendario!F:F))) -> 46087
A26: =IFERROR(IF(A25+1>$B$11," ",A25+1)," ") -> 6 | B26: =IFERROR(TEXT(R26,"DDD"),"") -> sáb | C26: =IF($G$13="Catorcenal",C25+14,_xlfn.XLOOKUP(A26,Calendario!G:G,Calendario!F:F)) -> 46102 | D26: =IFERROR(IF(D25+1>$B$11," ",D25+1)," ") -> 6 | E26: =IFERROR(IF(B26="dom",R26+1,R26)," ") -> 46102 | G26: =IFERROR(E26-E25,0) -> 15 | H26: =IF(D26=" ",0,IF(D26=$M$18,K26-I26-M26,ROUND($G$16-I26,2))) -> 99.91 | I26: =IFERROR(ROUND(IFERROR(L25*$H$8/30*G26," "),2),0) -> 79.01 | J26: =+M26 -> 8.75 | K26: =IF(D26=" "," ",K25) -> 187.67 | L26: =IF(H26=0," ",ROUND(IFERROR(L25-H26," "),2)) -> 2533.63 | M26: =IF(D26<=$M$18,$K$18,0) -> 8.75 | N26: =+H26+I26+J26-K26 -> 0 | O26: =IF(L26=MIN($L$21:$L$68),"min"," ") | P26: =IFERROR(IF(O26="Min",$T$13," "),"") | Q26: =IFERROR(R26-R25," ") -> 15 | R26: =IF(D26=" ","",IF($G$13="Catorcenal",R25+14,_xlfn.XLOOKUP(D26,Calendario!G:G,Calendario!F:F))) -> 46102
A27: =IFERROR(IF(A26+1>$B$11," ",A26+1)," ") -> 7 | B27: =IFERROR(TEXT(R27,"DDD"),"") -> lun | C27: =IF($G$13="Catorcenal",C26+14,_xlfn.XLOOKUP(A27,Calendario!G:G,Calendario!F:F)) -> 46118 | D27: =IFERROR(IF(D26+1>$B$11," ",D26+1)," ") -> 7 | E27: =IFERROR(IF(B27="dom",R27+1,R27)," ") -> 46118 | G27: =IFERROR(E27-E26,0) -> 16 | H27: =IF(D27=" ",0,IF(D27=$M$18,K27-I27-M27,ROUND($G$16-I27,2))) -> 97.84 | I27: =IFERROR(ROUND(IFERROR(L26*$H$8/30*G27," "),2),0) -> 81.08 | J27: =+M27 -> 8.75 | K27: =IF(D27=" "," ",K26) -> 187.67 | L27: =IF(H27=0," ",ROUND(IFERROR(L26-H27," "),2)) -> 2435.79 | M27: =IF(D27<=$M$18,$K$18,0) -> 8.75 | N27: =+H27+I27+J27-K27 -> 0 | O27: =IF(L27=MIN($L$21:$L$68),"min"," ") | P27: =IFERROR(IF(O27="Min",$T$13," "),"") | Q27: =IFERROR(R27-R26," ") -> 16 | R27: =IF(D27=" ","",IF($G$13="Catorcenal",R26+14,_xlfn.XLOOKUP(D27,Calendario!G:G,Calendario!F:F))) -> 46118
A28: =IFERROR(IF(A27+1>$B$11," ",A27+1)," ") -> 8 | B28: =IFERROR(TEXT(R28,"DDD"),"") -> mar | C28: =IF($G$13="Catorcenal",C27+14,_xlfn.XLOOKUP(A28,Calendario!G:G,Calendario!F:F)) -> 46133 | D28: =IFERROR(IF(D27+1>$B$11," ",D27+1)," ") -> 8 | E28: =IFERROR(IF(B28="dom",R28+1,R28)," ") -> 46133 | G28: =IFERROR(E28-E27,0) -> 15 | H28: =IF(D28=" ",0,IF(D28=$M$18,K28-I28-M28,ROUND($G$16-I28,2))) -> 105.85 | I28: =IFERROR(ROUND(IFERROR(L27*$H$8/30*G28," "),2),0) -> 73.07 | J28: =+M28 -> 8.75 | K28: =IF(D28=" "," ",K27) -> 187.67 | L28: =IF(H28=0," ",ROUND(IFERROR(L27-H28," "),2)) -> 2329.94 | M28: =IF(D28<=$M$18,$K$18,0) -> 8.75 | N28: =+H28+I28+J28-K28 -> 0 | O28: =IF(L28=MIN($L$21:$L$68),"min"," ") | P28: =IFERROR(IF(O28="Min",$T$13," "),"") | Q28: =IFERROR(R28-R27," ") -> 15 | R28: =IF(D28=" ","",IF($G$13="Catorcenal",R27+14,_xlfn.XLOOKUP(D28,Calendario!G:G,Calendario!F:F))) -> 46133
A29: =IFERROR(IF(A28+1>$B$11," ",A28+1)," ") -> 9 | B29: =IFERROR(TEXT(R29,"DDD"),"") -> mié | C29: =IF($G$13="Catorcenal",C28+14,_xlfn.XLOOKUP(A29,Calendario!G:G,Calendario!F:F)) -> 46148 | D29: =IFERROR(IF(D28+1>$B$11," ",D28+1)," ") -> 9 | E29: =IFERROR(IF(B29="dom",R29+1,R29)," ") -> 46148 | G29: =IFERROR(E29-E28,0) -> 15 | H29: =IF(D29=" ",0,IF(D29=$M$18,K29-I29-M29,ROUND($G$16-I29,2))) -> 109.02 | I29: =IFERROR(ROUND(IFERROR(L28*$H$8/30*G29," "),2),0) -> 69.9 | J29: =+M29 -> 8.75 | K29: =IF(D29=" "," ",K28) -> 187.67 | L29: =IF(H29=0," ",ROUND(IFERROR(L28-H29," "),2)) -> 2220.92 | M29: =IF(D29<=$M$18,$K$18,0) -> 8.75 | N29: =+H29+I29+J29-K29 -> 0 | O29: =IF(L29=MIN($L$21:$L$68),"min"," ") | P29: =IFERROR(IF(O29="Min",$T$13," "),"") | Q29: =IFERROR(R29-R28," ") -> 15 | R29: =IF(D29=" ","",IF($G$13="Catorcenal",R28+14,_xlfn.XLOOKUP(D29,Calendario!G:G,Calendario!F:F))) -> 46148
A30: =IFERROR(IF(A29+1>$B$11," ",A29+1)," ") -> 10 | B30: =IFERROR(TEXT(R30,"DDD"),"") -> jue | C30: =IF($G$13="Catorcenal",C29+14,_xlfn.XLOOKUP(A30,Calendario!G:G,Calendario!F:F)) -> 46163 | D30: =IFERROR(IF(D29+1>$B$11," ",D29+1)," ") -> 10 | E30: =IFERROR(IF(B30="dom",R30+1,R30)," ") -> 46163 | G30: =IFERROR(E30-E29,0) -> 15 | H30: =IF(D30=" ",0,IF(D30=$M$18,K30-I30-M30,ROUND($G$16-I30,2))) -> 112.29 | I30: =IFERROR(ROUND(IFERROR(L29*$H$8/30*G30," "),2),0) -> 66.63 | J30: =+M30 -> 8.75 | K30: =IF(D30=" "," ",K29) -> 187.67 | L30: =IF(H30=0," ",ROUND(IFERROR(L29-H30," "),2)) -> 2108.63 | M30: =IF(D30<=$M$18,$K$18,0) -> 8.75 | N30: =+H30+I30+J30-K30 -> 0 | O30: =IF(L30=MIN($L$21:$L$68),"min"," ") | P30: =IFERROR(IF(O30="Min",$T$13," "),"") | Q30: =IFERROR(R30-R29," ") -> 15 | R30: =IF(D30=" ","",IF($G$13="Catorcenal",R29+14,_xlfn.XLOOKUP(D30,Calendario!G:G,Calendario!F:F))) -> 46163
A31: =IFERROR(IF(A30+1>$B$11," ",A30+1)," ") -> 11 | B31: =IFERROR(TEXT(R31,"DDD"),"") -> sáb | C31: =IF($G$13="Catorcenal",C30+14,_xlfn.XLOOKUP(A31,Calendario!G:G,Calendario!F:F)) -> 46179 | D31: =IFERROR(IF(D30+1>$B$11," ",D30+1)," ") -> 11 | E31: =IFERROR(IF(B31="dom",R31+1,R31)," ") -> 46179 | G31: =IFERROR(E31-E30,0) -> 16 | H31: =IF(D31=" ",0,IF(D31=$M$18,K31-I31-M31,ROUND($G$16-I31,2))) -> 111.44 | I31: =IFERROR(ROUND(IFERROR(L30*$H$8/30*G31," "),2),0) -> 67.48 | J31: =+M31 -> 8.75 | K31: =IF(D31=" "," ",K30) -> 187.67 | L31: =IF(H31=0," ",ROUND(IFERROR(L30-H31," "),2)) -> 1997.19 | M31: =IF(D31<=$M$18,$K$18,0) -> 8.75 | N31: =+H31+I31+J31-K31 -> 0 | O31: =IF(L31=MIN($L$21:$L$68),"min"," ") | P31: =IFERROR(IF(O31="Min",$T$13," "),"") | Q31: =IFERROR(R31-R30," ") -> 16 | R31: =IF(D31=" ","",IF($G$13="Catorcenal",R30+14,_xlfn.XLOOKUP(D31,Calendario!G:G,Calendario!F:F))) -> 46179
A32: =IFERROR(IF(A31+1>$B$11," ",A31+1)," ") -> 12 | B32: =IFERROR(TEXT(R32,"DDD"),"") -> dom | C32: =IF($G$13="Catorcenal",C31+14,_xlfn.XLOOKUP(A32,Calendario!G:G,Calendario!F:F)) -> 46194 | D32: =IFERROR(IF(D31+1>$B$11," ",D31+1)," ") -> 12 | E32: =IFERROR(IF(B32="dom",R32+1,R32)," ") -> 46195 | G32: =IFERROR(E32-E31,0) -> 16 | H32: =IF(D32=" ",0,IF(D32=$M$18,K32-I32-M32,ROUND($G$16-I32,2))) -> 115.01 | I32: =IFERROR(ROUND(IFERROR(L31*$H$8/30*G32," "),2),0) -> 63.91 | J32: =+M32 -> 8.75 | K32: =IF(D32=" "," ",K31) -> 187.67 | L32: =IF(H32=0," ",ROUND(IFERROR(L31-H32," "),2)) -> 1882.18 | M32: =IF(D32<=$M$18,$K$18,0) -> 8.75 | N32: =+H32+I32+J32-K32 -> 0 | O32: =IF(L32=MIN($L$21:$L$68),"min"," ") | P32: =IFERROR(IF(O32="Min",$T$13," "),"") | Q32: =IFERROR(R32-R31," ") -> 15 | R32: =IF(D32=" ","",IF($G$13="Catorcenal",R31+14,_xlfn.XLOOKUP(D32,Calendario!G:G,Calendario!F:F))) -> 46194
A33: =IFERROR(IF(A32+1>$B$11," ",A32+1)," ") -> 13 | B33: =IFERROR(TEXT(R33,"DDD"),"") -> lun | C33: =IF($G$13="Catorcenal",C32+14,_xlfn.XLOOKUP(A33,Calendario!G:G,Calendario!F:F)) -> 46209 | D33: =IFERROR(IF(D32+1>$B$11," ",D32+1)," ") -> 13 | E33: =IFERROR(IF(B33="dom",R33+1,R33)," ") -> 46209 | G33: =IFERROR(E33-E32,0) -> 14 | H33: =IF(D33=" ",0,IF(D33=$M$18,K33-I33-M33,ROUND($G$16-I33,2))) -> 126.22 | I33: =IFERROR(ROUND(IFERROR(L32*$H$8/30*G33," "),2),0) -> 52.7 | J33: =+M33 -> 8.75 | K33: =IF(D33=" "," ",K32) -> 187.67 | L33: =IF(H33=0," ",ROUND(IFERROR(L32-H33," "),2)) -> 1755.96 | M33: =IF(D33<=$M$18,$K$18,0) -> 8.75 | N33: =+H33+I33+J33-K33 -> 0 | O33: =IF(L33=MIN($L$21:$L$68),"min"," ") | P33: =IFERROR(IF(O33="Min",$T$13," "),"") | Q33: =IFERROR(R33-R32," ") -> 15 | R33: =IF(D33=" ","",IF($G$13="Catorcenal",R32+14,_xlfn.XLOOKUP(D33,Calendario!G:G,Calendario!F:F))) -> 46209
A34: =IFERROR(IF(A33+1>$B$11," ",A33+1)," ") -> 14 | B34: =IFERROR(TEXT(R34,"DDD"),"") -> mar | C34: =IF($G$13="Catorcenal",C33+14,_xlfn.XLOOKUP(A34,Calendario!G:G,Calendario!F:F)) -> 46224 | D34: =IFERROR(IF(D33+1>$B$11," ",D33+1)," ") -> 14 | E34: =IFERROR(IF(B34="dom",R34+1,R34)," ") -> 46224 | G34: =IFERROR(E34-E33,0) -> 15 | H34: =IF(D34=" ",0,IF(D34=$M$18,K34-I34-M34,ROUND($G$16-I34,2))) -> 126.24 | I34: =IFERROR(ROUND(IFERROR(L33*$H$8/30*G34," "),2),0) -> 52.68 | J34: =+M34 -> 8.75 | K34: =IF(D34=" "," ",K33) -> 187.67 | L34: =IF(H34=0," ",ROUND(IFERROR(L33-H34," "),2)) -> 1629.72 | M34: =IF(D34<=$M$18,$K$18,0) -> 8.75 | N34: =+H34+I34+J34-K34 -> 0 | O34: =IF(L34=MIN($L$21:$L$68),"min"," ") | P34: =IFERROR(IF(O34="Min",$T$13," "),"") | Q34: =IFERROR(R34-R33," ") -> 15 | R34: =IF(D34=" ","",IF($G$13="Catorcenal",R33+14,_xlfn.XLOOKUP(D34,Calendario!G:G,Calendario!F:F))) -> 46224
A35: =IFERROR(IF(A34+1>$B$11," ",A34+1)," ") -> 15 | B35: =IFERROR(TEXT(R35,"DDD"),"") -> jue | C35: =IF($G$13="Catorcenal",C34+14,_xlfn.XLOOKUP(A35,Calendario!G:G,Calendario!F:F)) -> 46240 | D35: =IFERROR(IF(D34+1>$B$11," ",D34+1)," ") -> 15 | E35: =IFERROR(IF(B35="dom",R35+1,R35)," ") -> 46240 | G35: =IFERROR(E35-E34,0) -> 16 | H35: =IF(D35=" ",0,IF(D35=$M$18,K35-I35-M35,ROUND($G$16-I35,2))) -> 126.77 | I35: =IFERROR(ROUND(IFERROR(L34*$H$8/30*G35," "),2),0) -> 52.15 | J35: =+M35 -> 8.75 | K35: =IF(D35=" "," ",K34) -> 187.67 | L35: =IF(H35=0," ",ROUND(IFERROR(L34-H35," "),2)) -> 1502.95 | M35: =IF(D35<=$M$18,$K$18,0) -> 8.75 | N35: =+H35+I35+J35-K35 -> 0 | O35: =IF(L35=MIN($L$21:$L$68),"min"," ") | P35: =IFERROR(IF(O35="Min",$T$13," "),"") | Q35: =IFERROR(R35-R34," ") -> 16 | R35: =IF(D35=" ","",IF($G$13="Catorcenal",R34+14,_xlfn.XLOOKUP(D35,Calendario!G:G,Calendario!F:F))) -> 46240
... A42: =IFERROR(IF(A41+1>$B$11," ",A41+1)," ") -> 22 | B42: =IFERROR(TEXT(R42,"DDD"),"") -> sáb | C42: =IF($G$13="Catorcenal",C41+14,_xlfn.XLOOKUP(A42,Calendario!G:G,Calendario!F:F)) -> 46347 | D42: =IFERROR(IF(D41+1>$B$11," ",D41+1)," ") -> 22 | E42: =IFERROR(IF(B42="dom",R42+1,R42)," ") -> 46347 | G42: =IFERROR(E42-E41,0) -> 15 | H42: =IF(D42=" ",0,IF(D42=$M$18,K42-I42-M42,ROUND($G$16-I42,2))) -> 159.65 | I42: =IFERROR(ROUND(IFERROR(L41*$H$8/30*G42," "),2),0) -> 19.27 | J42: =+M42 -> 8.75 | K42: =IF(D42=" "," ",K41) -> 187.67 | L42: =IF(H42=0," ",ROUND(IFERROR(L41-H42," "),2)) -> 482.67 | M42: =IF(D42<=$M$18,$K$18,0) -> 8.75 | N42: =+H42+I42+J42-K42 -> 0 | O42: =IF(L42=MIN($L$21:$L$68),"min"," ") | P42: =IFERROR(IF(O42="Min",$T$13," "),"") | Q42: =IFERROR(R42-R41," ") -> 15 | R42: =IF(D42=" ","",IF($G$13="Catorcenal",R41+14,_xlfn.XLOOKUP(D42,Calendario!G:G,Calendario!F:F))) -> 46347
A43: =IFERROR(IF(A42+1>$B$11," ",A42+1)," ") -> 23 | B43: =IFERROR(TEXT(R43,"DDD"),"") -> dom | C43: =IF($G$13="Catorcenal",C42+14,_xlfn.XLOOKUP(A43,Calendario!G:G,Calendario!F:F)) -> 46362 | D43: =IFERROR(IF(D42+1>$B$11," ",D42+1)," ") -> 23 | E43: =IFERROR(IF(B43="dom",R43+1,R43)," ") -> 46363 | G43: =IFERROR(E43-E42,0) -> 16 | H43: =IF(D43=" ",0,IF(D43=$M$18,K43-I43-M43,ROUND($G$16-I43,2))) -> 163.47 | I43: =IFERROR(ROUND(IFERROR(L42*$H$8/30*G43," "),2),0) -> 15.45 | J43: =+M43 -> 8.75 | K43: =IF(D43=" "," ",K42) -> 187.67 | L43: =IF(H43=0," ",ROUND(IFERROR(L42-H43," "),2)) -> 319.2 | M43: =IF(D43<=$M$18,$K$18,0) -> 8.75 | O43: =IF(L43=MIN($L$21:$L$68),"min"," ") | P43: =IFERROR(IF(O43="Min",$T$13," "),"") | Q43: =IFERROR(R43-R42," ") -> 15 | R43: =IF(D43=" ","",IF($G$13="Catorcenal",R42+14,_xlfn.XLOOKUP(D43,Calendario!G:G,Calendario!F:F))) -> 46362
A44: =IFERROR(IF(A43+1>$B$11," ",A43+1)," ") -> 24 | B44: =IFERROR(TEXT(R44,"DDD"),"") -> lun | C44: =IF($G$13="Catorcenal",C43+14,_xlfn.XLOOKUP(A44,Calendario!G:G,Calendario!F:F)) -> 46377 | D44: =IFERROR(IF(D43+1>$B$11," ",D43+1)," ") -> 24 | E44: =IFERROR(IF(B44="dom",R44+1,R44)," ") -> 46377 | G44: =IFERROR(E44-E43,0) -> 14 | H44: =IF(D44=" ",0,IF(D44=$M$18,K44-I44-M44,ROUND($G$16-I44,2))) -> 319.2 | I44: =IFERROR(ROUND(IFERROR(L43*$H$8/30*G44," "),2),0) -> 8.94 | J44: =+M44 -> 8.75 | K44: 336.89 | L44: =IF(H44=0," ",ROUND(IFERROR(L43-H44," "),2)) -> 0 | M44: =IF(D44<=$M$18,$K$18,0) -> 8.75 | O44: =IF(L44=MIN($L$21:$L$68),"min"," ") -> min | P44: =IFERROR(IF(O44="Min",$T$13," "),"") -> 336.89 | Q44: =IFERROR(R44-R43," ") -> 15 | R44: =IF(D44=" ","",IF($G$13="Catorcenal",R43+14,_xlfn.XLOOKUP(D44,Calendario!G:G,Calendario!F:F))) -> 46377
A45: =IFERROR(IF(A44+1>$B$11," ",A44+1)," ") | B45: =IFERROR(TEXT(R45,"DDD"),"") | C45: =IF($G$13="Catorcenal",C44+14,_xlfn.XLOOKUP(A45,Calendario!G:G,Calendario!F:F)) -> #N/A | D45: =IFERROR(IF(D44+1>$B$11," ",D44+1)," ") | E45: =IFERROR(IF(B45="dom",R45+1,R45)," ") | G45: =IFERROR(E45-E44,0) -> 0 | H45: =IF(D45=" ",0,IF(D45=$M$18,K45-I45-M45,ROUND($G$16-I45,2))) -> 0 | I45: =IFERROR(ROUND(IFERROR(L44*$H$8/30*G45," "),2),0) -> 0 | J45: =+M45 -> 0 | K45: =IF(D45=" "," ",K44) | L45: =IF(H45=0," ",ROUND(IFERROR(L44-H45," "),2)) | M45: =IF(D45<=$M$18,$K$18,0) -> 0 | O45: =IF(L45=MIN($L$21:$L$68),"min"," ") | P45: =IFERROR(IF(O45="Min",$T$13," "),"") | Q45: =IFERROR(R45-R44," ") | R45: =IF(D45=" ","",IF($G$13="Catorcenal",R44+14,_xlfn.XLOOKUP(D45,Calendario!G:G,Calendario!F:F)))
A46: =IFERROR(IF(A45+1>$B$11," ",A45+1)," ") | B46: =IFERROR(TEXT(R46,"DDD"),"") | C46: =IF($G$13="Catorcenal",C45+14,_xlfn.XLOOKUP(A46,Calendario!G:G,Calendario!F:F)) -> #N/A | D46: =IFERROR(IF(D45+1>$B$11," ",D45+1)," ") | E46: =IFERROR(IF(B46="dom",R46+1,R46)," ") | G46: =IFERROR(E46-E45,0) -> 0 | H46: =IF(D46=" ",0,IF(D46=$M$18,K46-I46-M46,ROUND($G$16-I46,2))) -> 0 | I46: =IFERROR(ROUND(IFERROR(L45*$H$8/30*G46," "),2),0) -> 0 | J46: =+M46 -> 0 | K46: =IF(D46=" "," ",K45) | L46: =IF(H46=0," ",ROUND(IFERROR(L45-H46," "),2)) | M46: =IF(D46<=$M$18,$K$18,0) -> 0 | O46: =IF(L46=MIN($L$21:$L$68),"min"," ") | P46: =IFERROR(IF(O46="Min",$T$13," "),"") | Q46: =IFERROR(R46-R45," ") | R46: =IF(D46=" ","",IF($G$13="Catorcenal",R45+14,_xlfn.XLOOKUP(D46,Calendario!G:G,Calendario!F:F)))
A47: =IFERROR(IF(A46+1>$B$11," ",A46+1)," ") | B47: =IFERROR(TEXT(R47,"DDD"),"") | C47: =IF($G$13="Catorcenal",C46+14,_xlfn.XLOOKUP(A47,Calendario!G:G,Calendario!F:F)) -> #N/A | D47: =IFERROR(IF(D46+1>$B$11," ",D46+1)," ") | E47: =IFERROR(IF(B47="dom",R47+1,R47)," ") | G47: =IFERROR(E47-E46,0) -> 0 | H47: =IF(D47=" ",0,IF(D47=$M$18,K47-I47-M47,ROUND($G$16-I47,2))) -> 0 | I47: =IFERROR(ROUND(IFERROR(L46*$H$8/30*G47," "),2),0) -> 0 | J47: =+M47 -> 0 | K47: =IF(D47=" "," ",K46) | L47: =IF(H47=0," ",ROUND(IFERROR(L46-H47," "),2)) | M47: =IF(D47<=$M$18,$K$18,0) -> 0 | O47: =IF(L47=MIN($L$21:$L$68),"min"," ") | P47: =IFERROR(IF(O47="Min",$T$13," "),"") | Q47: =IFERROR(R47-R46," ") | R47: =IF(D47=" ","",IF($G$13="Catorcenal",R46+14,_xlfn.XLOOKUP(D47,Calendario!G:G,Calendario!F:F)))
A48: =IFERROR(IF(A47+1>$B$11," ",A47+1)," ") | B48: =IFERROR(TEXT(R48,"DDD"),"") | C48: =IF($G$13="Catorcenal",C47+14,_xlfn.XLOOKUP(A48,Calendario!G:G,Calendario!F:F)) -> #N/A | D48: =IFERROR(IF(D47+1>$B$11," ",D47+1)," ") | E48: =IFERROR(IF(B48="dom",R48+1,R48)," ") | G48: =IFERROR(E48-E47,0) -> 0 | H48: =IF(D48=" ",0,IF(D48=$M$18,K48-I48-M48,ROUND($G$16-I48,2))) -> 0 | I48: =IFERROR(ROUND(IFERROR(L47*$H$8/30*G48," "),2),0) -> 0 | J48: =+M48 -> 0 | K48: =IF(D48=" "," ",K47) | L48: =IF(H48=0," ",ROUND(IFERROR(L47-H48," "),2)) | M48: =IF(D48<=$M$18,$K$18,0) -> 0 | O48: =IF(L48=MIN($L$21:$L$68),"min"," ") | P48: =IFERROR(IF(O48="Min",$T$13," "),"") | Q48: =IFERROR(R48-R47," ") | R48: =IF(D48=" ","",IF($G$13="Catorcenal",R47+14,_xlfn.XLOOKUP(D48,Calendario!G:G,Calendario!F:F)))
A49: =IFERROR(IF(A48+1>$B$11," ",A48+1)," ") | B49: =IFERROR(TEXT(R49,"DDD"),"") | C49: =IF($G$13="Catorcenal",C48+14,_xlfn.XLOOKUP(A49,Calendario!G:G,Calendario!F:F)) -> #N/A | D49: =IFERROR(IF(D48+1>$B$11," ",D48+1)," ") | E49: =IFERROR(IF(B49="dom",R49+1,R49)," ") | G49: =IFERROR(E49-E48,0) -> 0 | H49: =IF(D49=" ",0,IF(D49=$M$18,K49-I49-M49,ROUND($G$16-I49,2))) -> 0 | I49: =IFERROR(ROUND(IFERROR(L48*$H$8/30*G49," "),2),0) -> 0 | J49: =+M49 -> 0 | K49: =IF(D49=" "," ",K48) | L49: =IF(H49=0," ",ROUND(IFERROR(L48-H49," "),2)) | M49: =IF(D49<=$M$18,$K$18,0) -> 0 | O49: =IF(L49=MIN($L$21:$L$68),"min"," ") | P49: =IFERROR(IF(O49="Min",$T$13," "),"") | Q49: =IFERROR(R49-R48," ") | R49: =IF(D49=" ","",IF($G$13="Catorcenal",R48+14,_xlfn.XLOOKUP(D49,Calendario!G:G,Calendario!F:F)))
A50: =IFERROR(IF(A49+1>$B$11," ",A49+1)," ") | B50: =IFERROR(TEXT(R50,"DDD"),"") | C50: =IF($G$13="Catorcenal",C49+14,_xlfn.XLOOKUP(A50,Calendario!G:G,Calendario!F:F)) -> #N/A | D50: =IFERROR(IF(D49+1>$B$11," ",D49+1)," ") | E50: =IFERROR(IF(B50="dom",R50+1,R50)," ") | G50: =IFERROR(E50-E49,0) -> 0 | H50: =IF(D50=" ",0,IF(D50=$M$18,K50-I50-M50,ROUND($G$16-I50,2))) -> 0 | I50: =IFERROR(ROUND(IFERROR(L49*$H$8/30*G50," "),2),0) -> 0 | J50: =+M50 -> 0 | K50: =IF(D50=" "," ",K49) | L50: =IF(H50=0," ",ROUND(IFERROR(L49-H50," "),2)) | M50: =IF(D50<=$M$18,$K$18,0) -> 0 | O50: =IF(L50=MIN($L$21:$L$68),"min"," ") | P50: =IFERROR(IF(O50="Min",$T$13," "),"") | Q50: =IFERROR(R50-R49," ") | R50: =IF(D50=" ","",IF($G$13="Catorcenal",R49+14,_xlfn.XLOOKUP(D50,Calendario!G:G,Calendario!F:F)))
...

Sheet Hoja3
A1: Cod | B1: Nª PRESTAMO | C1: Identificacion | D1: LAR | E1: Nombre
A2: 3 | B2: =+_xlfn.MAXIFS([1]Datos!$H:$H,[1]Datos!$B:$B,A2) -> #VALUE! | C2: 0012405850035D | D2: =+LEN(C2) -> 14 | E2: CHEYLA VANESSA MAYORGA SOZA
A3: 14 | B3: =+_xlfn.MAXIFS([1]Datos!$H:$H,[1]Datos!$B:$B,A3) -> #VALUE! | C3: 3213108920003F | D3: =+LEN(C3) -> 14 | E3: Liseth Ramona Toruño Sanchez
A4: 15 | B4: =+_xlfn.MAXIFS([1]Datos!$H:$H,[1]Datos!$B:$B,A4) -> #VALUE! | C4: 0010707780065A | D4: =+LEN(C4) -> 14 | E4: Mario Jose Blass Aleman
A5: 41 | B5: =+_xlfn.MAXIFS([1]Datos!$H:$H,[1]Datos!$B:$B,A5) -> #VALUE! | C5: 3660510740003S | D5: =+LEN(C5) -> 14 | E5: Martha Lorena Cisneros Gonzales
A6: 66 | B6: =+_xlfn.MAXIFS([1]Datos!$H:$H,[1]Datos!$B:$B,A6) -> #VALUE! | C6: 0011604510022A | D6: =+LEN(C6) -> 14 | E6: Gloria Argentina Aragon
A7: 87 | B7: =+_xlfn.MAXIFS([1]Datos!$H:$H,[1]Datos!$B:$B,A7) -> #VALUE! | C7: 0072606770001A | D7: =+LEN(C7) -> 14 | E7: Socorro Del Carmen Linares Aguirre
A8: 89 | B8: =+_xlfn.MAXIFS([1]Datos!$H:$H,[1]Datos!$B:$B,A8) -> #VALUE! | C8: 0072511850003P | D8: =+LEN(C8) -> 14 | E8: YAQUELIN ISABEL GONZALEZ ALTAMIRANO
A9: 116 | B9: =+_xlfn.MAXIFS([1]Datos!$H:$H,[1]Datos!$B:$B,A9) -> #VALUE! | C9: 4093105660002G | D9: =+LEN(C9) -> 14 | E9: JOSE YASMIN JARQUIN
A10: 126 | B10: =+_xlfn.MAXIFS([1]Datos!$H:$H,[1]Datos!$B:$B,A10) -> #VALUE! | C10: 2890504720001X | D10: =+LEN(C10) -> 14 | E10: Tomasa Delcarmen Mendoza Ruiz
A11: 128 | B11: =+_xlfn.MAXIFS([1]Datos!$H:$H,[1]Datos!$B:$B,A11) -> #VALUE! | C11: 0011503750059B | D11: =+LEN(C11) -> 14 | E11: Yamilett del Socorro Jimenez Hurtado
A12: 139 | B12: =+_xlfn.MAXIFS([1]Datos!$H:$H,[1]Datos!$B:$B,A12) -> #VALUE! | C12: 0011605760003V | D12: =+LEN(C12) -> 14 | E12: Mayra Veronica Mejia Vargas
A13: 140 | B13: =+_xlfn.MAXIFS([1]Datos!$H:$H,[1]Datos!$B:$B,A13) -> #VALUE! | C13: 0010305860050T | D13: =+LEN(C13) -> 14 | E13: Tomas Francisco Fernandez Perez
... A419: 1390 | B419: =+_xlfn.MAXIFS([1]Datos!$H:$H,[1]Datos!$B:$B,A419) -> #VALUE! | C419: 0010702680067Y | D419: =+LEN(C419) -> 14 | E419: Fatima Maria Bermudez Orozco
A420: 1391 | B420: 9081 | C420: 6111109620001X | D420: =+LEN(C420) -> 14 | E420: Elena Auxiliadora Reyes
A421: 1392 | B421: 9082 | C421: 0441209760000M | D421: =+LEN(C421) -> 14 | E421: Bernarda De los santos Cortez
A422: 1393 | B422: 9086 | C422: 2812002900011R | D422: =+LEN(C422) -> 14 | E422: Ana Bethlem Perez
A423: 1394 | B423: 9085 | C423: 0031409981002X | D423: =+LEN(C423) -> 14 | E423: Ninoska Del socorro Vidareyna
A424: 1395 | B424: 9084 | C424: 4412003700017V | D424: =+LEN(C424) -> 14 | E424: Aurora Siles Mejia
A425: 1396 | B425: 9087 | C425: 0010109810123W | D425: =+LEN(C425) -> 14 | E425: Wilfredo Antonio Leon
A426: 1397 | B426: 9088 | C426: 0011205900010X | D426: =+LEN(C426) -> 14 | E426: Jessenia Suyen Molina
A427: 1398 | B427: 9091 | C427: 4881001710001F | D427: =+LEN(C427) -> 14 | E427: Erika Vanessa Torrez
A428: 1399 | B428: 9093 | C428: 0012112690015H | D428: =+LEN(C428) -> 14 | E428: Myrian Del Carmen Moreno
A429: 1400 | B429: 9099 | C429: 0011405680072P | D429: =+LEN(C429) -> 14 | E429: Esther De los angeles Lopez
A430: 1401 | B430: 9106 | C430: 0010508850053B | D430: =+LEN(C430) -> 14 | E430: Wilmer Antonio Yescas
A431: 1402 | B431: 9107 | C431: 0012911991018V | D431: =+LEN(C431) -> 14 | E431: Julissa Tamara Chavarria

Sheet Hoja2
A1: =+'Plan de pagos'!R13 -> Segunda quincena | B1: Cantida de cuotas | C1: =IF('Plan de pagos'!G13="Mensual",'Plan de pagos'!G11,'Plan de pagos'!G11*2) -> 24 | E1: Mes | F1: =+MONTH(A2) -> 12 | H1: Año
A2: =+'Plan de pagos'!L13 -> 46015 | H2: 45854 | J2: =+DAY(H2) -> 16 | K2: =+IF(J2>14,"Segunda","Primera") -> Segunda
B3: 1 | C3: =+DAY(A2) -> 24 | E3: =+B3 -> 1 | H3: =+H2+I3 -> 45869 | I3: 15 | J3: =+DAY(H3) -> 31 | K3: =+IF(J3>14,"Segunda","Primera") -> Segunda
B4: =+IF(B3>=$C$1," ",B3+1) -> 2 | C4: =IF(B4=" ","",C3) -> 24 | E4: =+B4 -> 2 | H4: =+H3+I4 -> 45884 | I4: 15 | J4: =+DAY(H4) -> 15 | K4: =+IF(J4>14,"Segunda","Primera") -> Segunda | N4: 160
B5: =+IF(B4>=$C$1," ",B4+1) -> 3 | C5: =IF(B5=" ","",C4) -> 24 | E5: =+B5 -> 3 | H5: =+H4+I5 -> 45899 | I5: 15 | J5: =+DAY(H5) -> 30 | K5: =+IF(J5>14,"Segunda","Primera") -> Segunda | N5: 140
B6: =+IF(B5>=$C$1," ",B5+1) -> 4 | C6: =IF(B6=" ","",C5) -> 24 | E6: =+B6 -> 4 | H6: =+H5+I6 -> 45914 | I6: 15 | J6: =+DAY(H6) -> 14 | K6: =+IF(J6>14,"Segunda","Primera") -> Primera | N6: =+N5*37.07 -> 5189.8
B7: =+IF(B6>=$C$1," ",B6+1) -> 5 | C7: =IF(B7=" ","",C6) -> 24 | E7: =+B7 -> 5 | H7: =+H6+I7 -> 45929 | I7: 15 | J7: =+DAY(H7) -> 29 | K7: =+IF(J7>14,"Segunda","Primera") -> Segunda
B8: =+IF(B7>=$C$1," ",B7+1) -> 6 | C8: =IF(B8=" ","",C7) -> 24 | E8: =+B8 -> 6 | H8: =+H7+I8 -> 45944 | I8: 15 | J8: =+DAY(H8) -> 14 | K8: =+IF(J8>14,"Segunda","Primera") -> Primera
B9: =+IF(B8>=$C$1," ",B8+1) -> 7 | C9: =IF(B9=" ","",C8) -> 24 | E9: =+B9 -> 7 | H9: =+H8+I9 -> 45959 | I9: 15 | J9: =+DAY(H9) -> 29 | K9: =+IF(J9>14,"Segunda","Primera") -> Segunda
B10: =+IF(B9>=$C$1," ",B9+1) -> 8 | C10: =IF(B10=" ","",C9) -> 24 | E10: =+B10 -> 8 | H10: =+H9+I10 -> 45974 | I10: 15 | J10: =+DAY(H10) -> 13 | K10: =+IF(J10>14,"Segunda","Primera") -> Primera
B11: =+IF(B10>=$C$1," ",B10+1) -> 9 | C11: =IF(B11=" ","",C10) -> 24 | E11: =+B11 -> 9 | H11: =+H10+I11 -> 45989 | I11: 15 | J11: =+DAY(H11) -> 28 | K11: =+IF(J11>14,"Segunda","Primera") -> Segunda
B12: =+IF(B11>=$C$1," ",B11+1) -> 10 | C12: =IF(B12=" ","",C11) -> 24 | E12: =+B12 -> 10 | H12: =+H11+I12 -> 46004 | I12: 15 | J12: =+DAY(H12) -> 13 | K12: =+IF(J12>14,"Segunda","Primera") -> Primera
B13: =+IF(B12>=$C$1," ",B12+1) -> 11 | C13: =IF(B13=" ","",C12) -> 24 | E13: =+B13 -> 11 | H13: =+H12+I13 -> 46019 | I13: 15 | J13: =+DAY(H13) -> 28 | K13: =+IF(J13>14,"Segunda","Primera") -> Segunda
B14: =+IF(B13>=$C$1," ",B13+1) -> 12 | C14: =IF(B14=" ","",C13) -> 24 | E14: =+B14 -> 12 | H14: =+H13+I14 -> 46034 | I14: 15 | J14: =+DAY(H14) -> 12 | K14: =+IF(J14>14,"Segunda","Primera") -> Primera
B15: =+IF(B14>=$C$1," ",B14+1) -> 13 | C15: =IF(B15=" ","",C14) -> 24 | E15: =+B15 -> 13 | H15: =+H14+I15 -> 46049 | I15: 15 | J15: =+DAY(H15) -> 27 | K15: =+IF(J15>14,"Segunda","Primera") -> Segunda
B16: =+IF(B15>=$C$1," ",B15+1) -> 14 | C16: =IF(B16=" ","",C15) -> 24 | E16: =+B16 -> 14 | H16: =+H15+I16 -> 46064 | I16: 15 | J16: =+DAY(H16) -> 11 | K16: =+IF(J16>14,"Segunda","Primera") -> Primera
B17: =+IF(B16>=$C$1," ",B16+1) -> 15 | C17: =IF(B17=" ","",C16) -> 24 | E17: =+B17 -> 15 | H17: =+H16+I17 -> 46079 | I17: 15 | J17: =+DAY(H17) -> 26 | K17: =+IF(J17>14,"Segunda","Primera") -> Segunda
B18: =+IF(B17>=$C$1," ",B17+1) -> 16 | C18: =IF(B18=" ","",C17) -> 24 | E18: =+B18 -> 16 | H18: =+H17+I18 -> 46094 | I18: 15 | J18: =+DAY(H18) -> 13 | K18: =+IF(J18>14,"Segunda","Primera") -> Primera
B19: =+IF(B18>=$C$1," ",B18+1) -> 17 | C19: =IF(B19=" ","",C18) -> 24 | E19: =+B19 -> 17 | H19: =+H18+I19 -> 46109 | I19: 15 | J19: =+DAY(H19) -> 28 | K19: =+IF(J19>14,"Segunda","Primera") -> Segunda
B20: =+IF(B19>=$C$1," ",B19+1) -> 18 | C20: =IF(B20=" ","",C19) -> 24 | E20: =+B20 -> 18
B21: =+IF(B20>=$C$1," ",B20+1) -> 19 | C21: =IF(B21=" ","",C20) -> 24 | E21: =+B21 -> 19
B22: =+IF(B21>=$C$1," ",B21+1) -> 20 | C22: =IF(B22=" ","",C21) -> 24 | E22: =+B22 -> 20
B23: =+IF(B22>=$C$1," ",B22+1) -> 21 | C23: =IF(B23=" ","",C22) -> 24 | E23: =+B23 -> 21
B24: =+IF(B23>=$C$1," ",B23+1) -> 22 | C24: =IF(B24=" ","",C23) -> 24 | E24: =+B24 -> 22
B25: =+IF(B24>=$C$1," ",B24+1) -> 23 | C25: =IF(B25=" ","",C24) -> 24 | E25: =+B25 -> 23
B26: =+IF(B25>=$C$1," ",B25+1) -> 24 | C26: =IF(B26=" ","",C25) -> 24 | E26: =+B26 -> 24
B27: =+IF(B26>=$C$1," ",B26+1) | C27: =IF(B27=" ","",C26) | E27: =+B27
B28: =+IF(B27>=$C$1," ",B27+1) | C28: =IF(B28=" ","",C27) | E28: =+B28
B29: =+IF(B28>=$C$1," ",B28+1) | C29: =IF(B29=" ","",C28) | E29: =+B29
B30: =+IF(B29>=$C$1," ",B29+1) | C30: =IF(B30=" ","",C29) | E30: =+B30
B31: =+IF(B30>=$C$1," ",B30+1) | C31: =IF(B31=" ","",C30) | E31: =+B31
... B115: =+IF(B114>=$C$1," ",B114+1) | C115: =IF(B115=" ","",C114) | E115: =+B115
B116: =+IF(B115>=$C$1," ",B115+1) | C116: =IF(B116=" ","",C115)
B117: =+IF(B116>=$C$1," ",B116+1) | C117: =IF(B117=" ","",C116)

Sheet Calendario
M1: Primer | N1: segundo
L2: =+'Plan de pagos'!L13 -> 46015 | M2: =+'Plan de pagos'!H13 -> 6 | N2: =+'Plan de pagos'!I13 -> 21 | O2: =+IF(N2>28,"Maximo",0) -> 0
A3: 45658 | B3: =+IF(A3=$L$2,"Primer dia"," ") | C3: =+DAY(A3) -> 1 | D3: =+IF(A3=$L$2,"Primero"," ") | E3: =IF(B3=" "," ",IF(OR(C3=$M$2,C3=$N$2),C3," ")) | F3: =+IF(E3=" ","",A3) | G3: =IF(ISNUMBER(F3),COUNT($F$3:F3), "") | H3: =+IF(A3=EOMONTH(A3,0),DAY(A3)," ") | I3: =+IF(A3=$L$2,1,"")
A4: 45659 | B4: =+IF(A4=$L$2,"Primer dia",B3) | C4: =+DAY(A4) -> 2 | D4: =+IF(A4=$L$2,"Primero"," ") | E4: =IF(B4=" "," ",IF(OR(C4=$M$2,C4=$N$2),C4," ")) | F4: =+IF(E4=" ","",A4) | G4: =IF(ISNUMBER(F4),COUNT($F$3:F4), "") | H4: =+IF(A4=EOMONTH(A4,0),DAY(A4)," ") | I4: =+IF(A4=$L$2,1,"")
A5: 45660 | B5: =+IF(A5=$L$2,"Primer dia",B4) | C5: =+DAY(A5) -> 3 | D5: =+IF(A5=$L$2,"Primero"," ") | E5: =IF(B5=" "," ",IF(OR(C5=$M$2,C5=$N$2),C5," ")) | F5: =+IF(E5=" ","",A5) | G5: =IF(ISNUMBER(F5),COUNT($F$3:F5), "") | H5: =+IF(A5=EOMONTH(A5,0),DAY(A5)," ") | I5: =+IF(A5=$L$2,1,"")
A6: 45661 | B6: =+IF(A6=$L$2,"Primer dia",B5) | C6: =+DAY(A6) -> 4 | D6: =+IF(A6=$L$2,"Primero"," ") | E6: =IF(B6=" "," ",IF(OR(C6=$M$2,C6=$N$2),C6," ")) | F6: =+IF(E6=" ","",A6) | G6: =IF(ISNUMBER(F6),COUNT($F$3:F6), "") | H6: =+IF(A6=EOMONTH(A6,0),DAY(A6)," ") | I6: =+IF(A6=$L$2,1,"")
A7: 45662 | B7: =+IF(A7=$L$2,"Primer dia",B6) | C7: =+DAY(A7) -> 5 | D7: =+IF(A7=$L$2,"Primero"," ") | E7: =IF(B7=" "," ",IF(OR(C7=$M$2,C7=$N$2),C7," ")) | F7: =+IF(E7=" ","",A7) | G7: =IF(ISNUMBER(F7),COUNT($F$3:F7), "") | H7: =+IF(A7=EOMONTH(A7,0),DAY(A7)," ") | I7: =+IF(A7=$L$2,1,"")
A8: 45663 | B8: =+IF(A8=$L$2,"Primer dia",B7) | C8: =+DAY(A8) -> 6 | D8: =+IF(A8=$L$2,"Primero"," ") | E8: =IF(B8=" "," ",IF(OR(C8=$M$2,C8=$N$2),C8," ")) | F8: =+IF(E8=" ","",A8) | G8: =IF(ISNUMBER(F8),COUNT($F$3:F8), "") | H8: =+IF(A8=EOMONTH(A8,0),DAY(A8)," ") | I8: =+IF(A8=$L$2,1,"")
A9: 45664 | B9: =+IF(A9=$L$2,"Primer dia",B8) | C9: =+DAY(A9) -> 7 | D9: =+IF(A9=$L$2,"Primero"," ") | E9: =IF(B9=" "," ",IF(OR(C9=$M$2,C9=$N$2),C9," ")) | F9: =+IF(E9=" ","",A9) | G9: =IF(ISNUMBER(F9),COUNT($F$3:F9), "") | H9: =+IF(A9=EOMONTH(A9,0),DAY(A9)," ") | I9: =+IF(A9=$L$2,1,"")
A10: 45665 | B10: =+IF(A10=$L$2,"Primer dia",B9) | C10: =+DAY(A10) -> 8 | D10: =+IF(A10=$L$2,"Primero"," ") | E10: =IF(B10=" "," ",IF(OR(C10=$M$2,C10=$N$2),C10," ")) | F10: =+IF(E10=" ","",A10) | G10: =IF(ISNUMBER(F10),COUNT($F$3:F10), "") | H10: =+IF(A10=EOMONTH(A10,0),DAY(A10)," ") | I10: =+IF(A10=$L$2,1,"")
A11: 45666 | B11: =+IF(A11=$L$2,"Primer dia",B10) | C11: =+DAY(A11) -> 9 | D11: =+IF(A11=$L$2,"Primero"," ") | E11: =IF(B11=" "," ",IF(OR(C11=$M$2,C11=$N$2),C11," ")) | F11: =+IF(E11=" ","",A11) | G11: =IF(ISNUMBER(F11),COUNT($F$3:F11), "") | H11: =+IF(A11=EOMONTH(A11,0),DAY(A11)," ") | I11: =+IF(A11=$L$2,1,"")
A12: 45667 | B12: =+IF(A12=$L$2,"Primer dia",B11) | C12: =+DAY(A12) -> 10 | D12: =+IF(A12=$L$2,"Primero"," ") | E12: =IF(B12=" "," ",IF(OR(C12=$M$2,C12=$N$2),C12," ")) | F12: =+IF(E12=" ","",A12) | G12: =IF(ISNUMBER(F12),COUNT($F$3:F12), "") | H12: =+IF(A12=EOMONTH(A12,0),DAY(A12)," ") | I12: =+IF(A12=$L$2,1,"")
A13: 45668 | B13: =+IF(A13=$L$2,"Primer dia",B12) | C13: =+DAY(A13) -> 11 | D13: =+IF(A13=$L$2,"Primero"," ") | E13: =IF(B13=" "," ",IF(OR(C13=$M$2,C13=$N$2),C13," ")) | F13: =+IF(E13=" ","",A13) | G13: =IF(ISNUMBER(F13),COUNT($F$3:F13), "") | H13: =+IF(A13=EOMONTH(A13,0),DAY(A13)," ") | I13: =+IF(A13=$L$2,1,"")
A14: 45669 | B14: =+IF(A14=$L$2,"Primer dia",B13) | C14: =+DAY(A14) -> 12 | D14: =+IF(A14=$L$2,"Primero"," ") | E14: =IF(B14=" "," ",IF(OR(C14=$M$2,C14=$N$2),C14," ")) | F14: =+IF(E14=" ","",A14) | G14: =IF(ISNUMBER(F14),COUNT($F$3:F14), "") | H14: =+IF(A14=EOMONTH(A14,0),DAY(A14)," ") | I14: =+IF(A14=$L$2,1,"")
A15: 45670 | B15: =+IF(A15=$L$2,"Primer dia",B14) | C15: =+DAY(A15) -> 13 | D15: =+IF(A15=$L$2,"Primero"," ") | E15: =IF(B15=" "," ",IF(OR(C15=$M$2,C15=$N$2),C15," ")) | F15: =+IF(E15=" ","",A15) | G15: =IF(ISNUMBER(F15),COUNT($F$3:F15), "") | H15: =+IF(A15=EOMONTH(A15,0),DAY(A15)," ") | I15: =+IF(A15=$L$2,1,"")
... A181: 45836 | B181: =+IF(A181=$L$2,"Primer dia",B180) | C181: =+DAY(A181) -> 28 | D181: =+IF(A181=$L$2,"Primero"," ") | E181: =IF(B181=" "," ",IF(OR(C181=$M$2,C181=$N$2),C181," ")) | F181: =+IF(E181=" ","",A181) | G181: =IF(ISNUMBER(F181),COUNT($F$3:F181), "") | H181: =+IF(A181=EOMONTH(A181,0),DAY(A181)," ") | I181: =+IF(A181=$L$2,1,"")
A182: 45837 | B182: =+IF(A182=$L$2,"Primer dia",B181) | C182: =+DAY(A182) -> 29 | D182: =+IF(A182=$L$2,"Primero"," ") | E182: =IF(AND(H182>=28,H182<=29),H182,IF(B182=" "," ",IF(OR(C182=$M$2,C182=$N$2),C182," "))) | F182: =+IF(E182=" ","",A182) | G182: =IF(ISNUMBER(F182),COUNT($F$3:F182), "") | H182: =+IF(A182=EOMONTH(A182,0),DAY(A182)," ") | I182: =+IF(A182=$L$2,1,"")
A183: 45838 | B183: =+IF(A183=$L$2,"Primer dia",B182) | C183: =+DAY(A183) -> 30 | D183: =+IF(A183=$L$2,"Primero"," ") | E183: =IF(AND(H183>=28,H183<=29),H183,IF(B183=" "," ",IF(OR(C183=$M$2,C183=$N$2),C183," "))) | F183: =+IF(E183=" ","",A183) | G183: =IF(ISNUMBER(F183),COUNT($F$3:F183), "") | H183: =+IF(A183=EOMONTH(A183,0),DAY(A183)," ") -> 30 | I183: =+IF(A183=$L$2,1,"")
A184: 45839 | B184: =+IF(A184=$L$2,"Primer dia",B183) | C184: =+DAY(A184) -> 1 | D184: =+IF(A184=$L$2,"Primero"," ") | E184: =IF(AND(H184>=28,H184<=29),H184,IF(B184=" "," ",IF(OR(C184=$M$2,C184=$N$2),C184," "))) | F184: =+IF(E184=" ","",A184) | G184: =IF(ISNUMBER(F184),COUNT($F$3:F184), "") | H184: =+IF(A184=EOMONTH(A184,0),DAY(A184)," ") | I184: =+IF(A184=$L$2,1,"")
A185: 45840 | B185: =+IF(A185=$L$2,"Primer dia",B184) | C185: =+DAY(A185) -> 2 | D185: =+IF(A185=$L$2,"Primero"," ") | E185: =IF(AND(H185>=28,H185<=29),H185,IF(B185=" "," ",IF(OR(C185=$M$2,C185=$N$2),C185," "))) | F185: =+IF(E185=" ","",A185) | G185: =IF(ISNUMBER(F185),COUNT($F$3:F185), "") | H185: =+IF(A185=EOMONTH(A185,0),DAY(A185)," ") | I185: =+IF(A185=$L$2,1,"")
A186: 45841 | B186: =+IF(A186=$L$2,"Primer dia",B185) | C186: =+DAY(A186) -> 3 | D186: =+IF(A186=$L$2,"Primero"," ") | E186: =IF(AND(H186>=28,H186<=29),H186,IF(B186=" "," ",IF(OR(C186=$M$2,C186=$N$2),C186," "))) | F186: =+IF(E186=" ","",A186) | G186: =IF(ISNUMBER(F186),COUNT($F$3:F186), "") | H186: =+IF(A186=EOMONTH(A186,0),DAY(A186)," ") | I186: =+IF(A186=$L$2,1,"")
A187: 45842 | B187: =+IF(A187=$L$2,"Primer dia",B186) | C187: =+DAY(A187) -> 4 | D187: =+IF(A187=$L$2,"Primero"," ") | E187: =IF(AND(H187>=28,H187<=29),H187,IF(B187=" "," ",IF(OR(C187=$M$2,C187=$N$2),C187," "))) | F187: =+IF(E187=" ","",A187) | G187: =IF(ISNUMBER(F187),COUNT($F$3:F187), "") | H187: =+IF(A187=EOMONTH(A187,0),DAY(A187)," ") | I187: =+IF(A187=$L$2,1,"")
A188: 45843 | B188: =+IF(A188=$L$2,"Primer dia",B187) | C188: =+DAY(A188) -> 5 | D188: =+IF(A188=$L$2,"Primero"," ") | E188: =IF(AND(H188>=28,H188<=29),H188,IF(B188=" "," ",IF(OR(C188=$M$2,C188=$N$2),C188," "))) | F188: =+IF(E188=" ","",A188) | G188: =IF(ISNUMBER(F188),COUNT($F$3:F188), "") | H188: =+IF(A188=EOMONTH(A188,0),DAY(A188)," ") | I188: =+IF(A188=$L$2,1,"")
A189: 45844 | B189: =+IF(A189=$L$2,"Primer dia",B188) | C189: =+DAY(A189) -> 6 | D189: =+IF(A189=$L$2,"Primero"," ") | E189: =IF(AND(H189>=28,H189<=29),H189,IF(B189=" "," ",IF(OR(C189=$M$2,C189=$N$2),C189," "))) | F189: =+IF(E189=" ","",A189) | G189: =IF(ISNUMBER(F189),COUNT($F$3:F189), "") | H189: =+IF(A189=EOMONTH(A189,0),DAY(A189)," ") | I189: =+IF(A189=$L$2,1,"")
A190: 45845 | B190: =+IF(A190=$L$2,"Primer dia",B189) | C190: =+DAY(A190) -> 7 | D190: =+IF(A190=$L$2,"Primero"," ") | E190: =IF(AND(H190>=28,H190<=29),H190,IF(B190=" "," ",IF(OR(C190=$M$2,C190=$N$2),C190," "))) | F190: =+IF(E190=" ","",A190) | G190: =IF(ISNUMBER(F190),COUNT($F$3:F190), "") | H190: =+IF(A190=EOMONTH(A190,0),DAY(A190)," ") | I190: =+IF(A190=$L$2,1,"")
A191: 45846 | B191: =+IF(A191=$L$2,"Primer dia",B190) | C191: =+DAY(A191) -> 8 | D191: =+IF(A191=$L$2,"Primero"," ") | E191: =IF(AND(H191>=28,H191<=29),H191,IF(B191=" "," ",IF(OR(C191=$M$2,C191=$N$2),C191," "))) | F191: =+IF(E191=" ","",A191) | G191: =IF(ISNUMBER(F191),COUNT($F$3:F191), "") | H191: =+IF(A191=EOMONTH(A191,0),DAY(A191)," ") | I191: =+IF(A191=$L$2,1,"")
A192: 45847 | B192: =+IF(A192=$L$2,"Primer dia",B191) | C192: =+DAY(A192) -> 9 | D192: =+IF(A192=$L$2,"Primero"," ") | E192: =IF(AND(H192>=28,H192<=29),H192,IF(B192=" "," ",IF(OR(C192=$M$2,C192=$N$2),C192," "))) | F192: =+IF(E192=" ","",A192) | G192: =IF(ISNUMBER(F192),COUNT($F$3:F192), "") | H192: =+IF(A192=EOMONTH(A192,0),DAY(A192)," ") | I192: =+IF(A192=$L$2,1,"")
A193: 45848 | B193: =+IF(A193=$L$2,"Primer dia",B192) | C193: =+DAY(A193) -> 10 | D193: =+IF(A193=$L$2,"Primero"," ") | E193: =IF(AND(H193>=28,H193<=29),H193,IF(B193=" "," ",IF(OR(C193=$M$2,C193=$N$2),C193," "))) | F193: =+IF(E193=" ","",A193) | G193: =IF(ISNUMBER(F193),COUNT($F$3:F193), "") | H193: =+IF(A193=EOMONTH(A193,0),DAY(A193)," ") | I193: =+IF(A193=$L$2,1,"") | K193: =140*37.07 -> 5189.8 | L193: =5200-K193 -> 10.2
A194: 45849 | B194: =+IF(A194=$L$2,"Primer dia",B193) | C194: =+DAY(A194) -> 11 | D194: =+IF(A194=$L$2,"Primero"," ") | E194: =IF(AND(H194>=28,H194<=29),H194,IF(B194=" "," ",IF(OR(C194=$M$2,C194=$N$2),C194," "))) | F194: =+IF(E194=" ","",A194) | G194: =IF(ISNUMBER(F194),COUNT($F$3:F194), "") | H194: =+IF(A194=EOMONTH(A194,0),DAY(A194)," ") | I194: =+IF(A194=$L$2,1,"")
A195: 45850 | B195: =+IF(A195=$L$2,"Primer dia",B194) | C195: =+DAY(A195) -> 12 | D195: =+IF(A195=$L$2,"Primero"," ") | E195: =IF(AND(H195>=28,H195<=29),H195,IF(B195=" "," ",IF(OR(C195=$M$2,C195=$N$2),C195," "))) | F195: =+IF(E195=" ","",A195) | G195: =IF(ISNUMBER(F195),COUNT($F$3:F195), "") | H195: =+IF(A195=EOMONTH(A195,0),DAY(A195)," ") | I195: =+IF(A195=$L$2,1,"")
A196: 45851 | B196: =+IF(A196=$L$2,"Primer dia",B195) | C196: =+DAY(A196) -> 13 | D196: =+IF(A196=$L$2,"Primero"," ") | E196: =IF(AND(H196>=28,H196<=29),H196,IF(B196=" "," ",IF(OR(C196=$M$2,C196=$N$2),C196," "))) | F196: =+IF(E196=" ","",A196) | G196: =IF(ISNUMBER(F196),COUNT($F$3:F196), "") | H196: =+IF(A196=EOMONTH(A196,0),DAY(A196)," ") | I196: =+IF(A196=$L$2,1,"")
A197: 45852 | B197: =+IF(A197=$L$2,"Primer dia",B196) | C197: =+DAY(A197) -> 14 | D197: =+IF(A197=$L$2,"Primero"," ") | E197: =IF(AND(H197>=28,H197<=29),H197,IF(B197=" "," ",IF(OR(C197=$M$2,C197=$N$2),C197," "))) | F197: =+IF(E197=" ","",A197) | G197: =IF(ISNUMBER(F197),COUNT($F$3:F197), "") | H197: =+IF(A197=EOMONTH(A197,0),DAY(A197)," ") | I197: =+IF(A197=$L$2,1,"")
A198: 45853 | B198: =+IF(A198=$L$2,"Primer dia",B197) | C198: =+DAY(A198) -> 15 | D198: =+IF(A198=$L$2,"Primero"," ") | E198: =IF(AND(H198>=28,H198<=29),H198,IF(B198=" "," ",IF(OR(C198=$M$2,C198=$N$2),C198," "))) | F198: =+IF(E198=" ","",A198) | G198: =IF(ISNUMBER(F198),COUNT($F$3:F198), "") | H198: =+IF(A198=EOMONTH(A198,0),DAY(A198)," ") | I198: =+IF(A198=$L$2,1,"")
A199: 45854 | B199: =+IF(A199=$L$2,"Plan de pago",B198) | C199: =+DAY(A199) -> 16 | D199: =+IF(A199=$L$2,"Primero"," ") | E199: =IF(AND(H199>=28,H199<=29),H199,IF(B199=" "," ",IF(OR(C199=$M$2,C199=$N$2),C199," "))) | F199: =+IF(E199=" ","",A199) | G199: =IF(ISNUMBER(F199),COUNT($F$3:F199), "") | H199: =+IF(A199=EOMONTH(A199,0),DAY(A199)," ") | I199: =+IF(A199=$L$2,1,"")
A200: 45855 | B200: =+IF(A200=$L$2,"Primer dia",B199) | C200: =+DAY(A200) -> 17 | D200: =+IF(A200=$L$2,"Primero"," ") | E200: =IF(AND(H200>=28,H200<=29),H200,IF(B200=" "," ",IF(OR(C200=$M$2,C200=$N$2),C200," "))) | F200: =+IF(E200=" ","",A200) | G200: =IF(ISNUMBER(F200),COUNT($F$3:F200), "") | H200: =+IF(A200=EOMONTH(A200,0),DAY(A200)," ") | I200: =+IF(A200=$L$2,1,"")
A201: 45856 | B201: =+IF(A201=$L$2,"Primer dia",B200) | C201: =+DAY(A201) -> 18 | D201: =+IF(A201=$L$2,"Primero"," ") | E201: =IF(AND(H201>=28,H201<=29),H201,IF(B201=" "," ",IF(OR(C201=$M$2,C201=$N$2),C201," "))) | F201: =+IF(E201=" ","",A201) | G201: =IF(ISNUMBER(F201),COUNT($F$3:F201), "") | H201: =+IF(A201=EOMONTH(A201,0),DAY(A201)," ") | I201: =+IF(A201=$L$2,1,"")
A202: 45857 | B202: =+IF(A202=$L$2,"Primer dia",B201) | C202: =+DAY(A202) -> 19 | D202: =+IF(A202=$L$2,"Primero"," ") | E202: =IF(AND(H202>=28,H202<=29),H202,IF(B202=" "," ",IF(OR(C202=$M$2,C202=$N$2),C202," "))) | F202: =+IF(E202=" ","",A202) | G202: =IF(ISNUMBER(F202),COUNT($F$3:F202), "") | H202: =+IF(A202=EOMONTH(A202,0),DAY(A202)," ") | I202: =+IF(A202=$L$2,1,"")
A203: 45858 | B203: =+IF(A203=$L$2,"Primer dia",B202) | C203: =+DAY(A203) -> 20 | D203: =+IF(A203=$L$2,"Primero"," ") | E203: =IF(AND(H203>=28,H203<=29),H203,IF(B203=" "," ",IF(OR(C203=$M$2,C203=$N$2),C203," "))) | F203: =+IF(E203=" ","",A203) | G203: =IF(ISNUMBER(F203),COUNT($F$3:F203), "") | H203: =+IF(A203=EOMONTH(A203,0),DAY(A203)," ") | I203: =+IF(A203=$L$2,1,"")
A204: 45859 | B204: =+IF(A204=$L$2,"Primer dia",B203) | C204: =+DAY(A204) -> 21 | D204: =+IF(A204=$L$2,"Primero"," ") | E204: =IF(AND(H204>=28,H204<=29),H204,IF(B204=" "," ",IF(OR(C204=$M$2,C204=$N$2),C204," "))) | F204: =+IF(E204=" ","",A204) | G204: =IF(ISNUMBER(F204),COUNT($F$3:F204), "") | H204: =+IF(A204=EOMONTH(A204,0),DAY(A204)," ") | I204: =+IF(A204=$L$2,1,"")
A205: 45860 | B205: =+IF(A205=$L$2,"Primer dia",B204) | C205: =+DAY(A205) -> 22 | D205: =+IF(A205=$L$2,"Primero"," ") | E205: =IF(AND(H205>=28,H205<=29),H205,IF(B205=" "," ",IF(OR(C205=$M$2,C205=$N$2),C205," "))) | F205: =+IF(E205=" ","",A205) | G205: =IF(ISNUMBER(F205),COUNT($F$3:F205), "") | H205: =+IF(A205=EOMONTH(A205,0),DAY(A205)," ") | I205: =+IF(A205=$L$2,1,"")
...

Sheet Hoja1
